Workbook

Sheet Combined Summary
A1: Item name | B1: Category | C1: Size / Variant | D1: Promenade | E1: Bedaya | F1: Combined Total
A2: Kyokushin Gloves (White) | B2: Protective Gear | C2: Small | D2: =SUMPRODUCT((Promenade!$B$2:$B$200=$A2)*(Promenade!$D$2:$D$200=$C2),Promenade!$E$2:$E$200) -> 0 | E2: =SUMPRODUCT((Bedaya!$B$2:$B$200=$A2)*(Bedaya!$D$2:$D$200=$C2),Bedaya!$E$2:$E$200) -> 1 | F2: =SUM(D2:E2) -> 1
A3: Kyokushin Gloves (White) | B3: Protective Gear | C3: XS | D3: =SUMPRODUCT((Promenade!$B$2:$B$200=$A3)*(Promenade!$D$2:$D$200=$C3),Promenade!$E$2:$E$200) -> 0 | E3: =SUMPRODUCT((Bedaya!$B$2:$B$200=$A3)*(Bedaya!$D$2:$D$200=$C3),Bedaya!$E$2:$E$200) -> 2 | F3: =SUM(D3:E3) -> 2
A4: Mouth Guard | B4: Protective Gear | C4: Small | D4: =SUMPRODUCT((Promenade!$B$2:$B$200=$A4)*(Promenade!$D$2:$D$200=$C4),Promenade!$E$2:$E$200) -> 0 | E4: =SUMPRODUCT((Bedaya!$B$2:$B$200=$A4)*(Bedaya!$D$2:$D$200=$C4),Bedaya!$E$2:$E$200) -> 2 | F4: =SUM(D4:E4) -> 2
A5: Mouth Guard | B5: Protective Gear | C5: Junior | D5: =SUMPRODUCT((Promenade!$B$2:$B$200=$A5)*(Promenade!$D$2:$D$200=$C5),Promenade!$E$2:$E$200) -> 0 | E5: =SUMPRODUCT((Bedaya!$B$2:$B$200=$A5)*(Bedaya!$D$2:$D$200=$C5),Bedaya!$E$2:$E$200) -> 12 | F5: =SUM(D5:E5) -> 12
A6: Supporter | B6: Protective Gear | C6: M | D6: =SUMPRODUCT((Promenade!$B$2:$B$200=$A6)*(Promenade!$D$2:$D$200=$C6),Promenade!$E$2:$E$200) -> 0 | E6: =SUMPRODUCT((Bedaya!$B$2:$B$200=$A6)*(Bedaya!$D$2:$D$200=$C6),Bedaya!$E$2:$E$200) -> 7 | F6: =SUM(D6:E6) -> 7
A7: Supporter | B7: Protective Gear | C7: S | D7: =SUMPRODUCT((Promenade!$B$2:$B$200=$A7)*(Promenade!$D$2:$D$200=$C7),Promenade!$E$2:$E$200) -> 0 | E7: =SUMPRODUCT((Bedaya!$B$2:$B$200=$A7)*(Bedaya!$D$2:$D$200=$C7),Bedaya!$E$2:$E$200) -> 9 | F7: =SUM(D7:E7) -> 9
A8: Shin Guard | B8: Protective Gear | C8: XL | D8: =SUMPRODUCT((Promenade!$B$2:$B$200=$A8)*(Promenade!$D$2:$D$200=$C8),Promenade!$E$2:$E$200) -> 2 | E8: =SUMPRODUCT((Bedaya!$B$2:$B$200=$A8)*(Bedaya!$D$2:$D$200=$C8),Bedaya!$E$2:$E$200) -> -1 | F8: =SUM(D8:E8) -> 1
A9: Shin Guard | B9: Protective Gear | C9: L | D9: =SUMPRODUCT((Promenade!$B$2:$B$200=$A9)*(Promenade!$D$2:$D$200=$C9),Promenade!$E$2:$E$200) -> 4 | E9: =SUMPRODUCT((Bedaya!$B$2:$B$200=$A9)*(Bedaya!$D$2:$D$200=$C9),Bedaya!$E$2:$E$200) -> 0 | F9: =SUM(D9:E9) -> 4
A10: Shin Guard | B10: Protective Gear | C10: M | D10: =SUMPRODUCT((Promenade!$B$2:$B$200=$A10)*(Promenade!$D$2:$D$200=$C10),Promenade!$E$2:$E$200) -> 2 | E10: =SUMPRODUCT((Bedaya!$B$2:$B$200=$A10)*(Bedaya!$D$2:$D$200=$C10),Bedaya!$E$2:$E$200) -> -1 | F10: =SUM(D10:E10) -> 1
A11: Shin Guard | B11: Protective Gear | C11: S | D11: =SUMPRODUCT((Promenade!$B$2:$B$200=$A11)*(Promenade!$D$2:$D$200=$C11),Promenade!$E$2:$E$200) -> 1 | E11: =SUMPRODUCT((Bedaya!$B$2:$B$200=$A11)*(Bedaya!$D$2:$D$200=$C11),Bedaya!$E$2:$E$200) -> 0 | F11: =SUM(D11:E11) -> 1
A12: Shin Guard | B12: Protective Gear | C12: XS | D12: =SUMPRODUCT((Promenade!$B$2:$B$200=$A12)*(Promenade!$D$2:$D$200=$C12),Promenade!$E$2:$E$200) -> 2 | E12: =SUMPRODUCT((Bedaya!$B$2:$B$200=$A12)*(Bedaya!$D$2:$D$200=$C12),Bedaya!$E$2:$E$200) -> 0 | F12: =SUM(D12:E12) -> 2
A13: Boxing Gloves | B13: Protective Gear | C13: 12oz | D13: =SUMPRODUCT((Promenade!$B$2:$B$200=$A13)*(Promenade!$D$2:$D$200=$C13),Promenade!$E$2:$E$200) -> 1 | E13: =SUMPRODUCT((Bedaya!$B$2:$B$200=$A13)*(Bedaya!$D$2:$D$200=$C13),Bedaya!$E$2:$E$200) -> 0 | F13: =SUM(D13:E13) -> 1
... A126: Damaged Items (item not specified) | B126: Damaged | C126: 120cm | D126: =SUMPRODUCT((Promenade!$B$2:$B$200=$A126)*(Promenade!$D$2:$D$200=$C126),Promenade!$E$2:$E$200) -> 1 | E126: =SUMPRODUCT((Bedaya!$B$2:$B$200=$A126)*(Bedaya!$D$2:$D$200=$C126),Bedaya!$E$2:$E$200) -> 0 | F126: =SUM(D126:E126) -> 1
A128: Note: quantities are pulled by formula from the Promenade and Bedaya sheets (matched on Item name + Size / Variant). Items added on a branch sheet with a new name/size need a new row here.

Sheet Promenade
A1: Branch | B1: Item name | C1: Category | D1: Size / Variant | E1: Quantity counted | F1: Unit | G1: Reorder level | H1: Unit cost | I1: Total value | J1: Notes
A2: Promenade | B2: Kajukimbo Patch - Shoulder | C2: Patches & Badges | D2: - | E2: 6 | F2: pcs | I2: =IF(OR(E2="",H2=""),"",E2*H2) | J2: 20 Sep 2026 - stock remaining | Listed in Argan count as 'already in Elite Promenade'
A3: Promenade | B3: Kajukimbo Patch - Circle (Front) | C3: Patches & Badges | D3: - | E3: 6 | F3: pcs | I3: =IF(OR(E3="",H3=""),"",E3*H3) | J3: 20 Sep 2026 - stock remaining | Listed as 'Front Patch' - assumed same as Circle (Front)
A4: Promenade | B4: Boxing Gloves | C4: Protective Gear | D4: 6oz | E4: 2 | F4: pairs | I4: =IF(OR(E4="",H4=""),"",E4*H4) | J4: 19 Sep 2026 - received from Bedaya (transfer)
A5: Promenade | B5: Boxing Gloves | C5: Protective Gear | D5: 8oz | E5: 2 | F5: pairs | I5: =IF(OR(E5="",H5=""),"",E5*H5) | J5: 19 Sep 2026 - received from Bedaya (transfer)
A6: Promenade | B6: Boxing Gloves | C6: Protective Gear | D6: 10oz | E6: 2 | F6: pairs | I6: =IF(OR(E6="",H6=""),"",E6*H6) | J6: 19 Sep 2026 - received from Bedaya (transfer)
A7: Promenade | B7: Boxing Gloves | C7: Protective Gear | D7: 12oz | E7: 1 | F7: pairs | I7: =IF(OR(E7="",H7=""),"",E7*H7) | J7: 19 Sep 2026 - received from Bedaya (transfer)
A8: Promenade | B8: Shin Guard | C8: Protective Gear | D8: XS | E8: 2 | F8: pairs | I8: =IF(OR(E8="",H8=""),"",E8*H8) | J8: 19 Sep 2026 - received from Bedaya (transfer)
A9: Promenade | B9: Shin Guard | C9: Protective Gear | D9: S | E9: 1 | F9: pairs | I9: =IF(OR(E9="",H9=""),"",E9*H9) | J9: 19 Sep 2026 - received from Bedaya (transfer)
A10: Promenade | B10: Shin Guard | C10: Protective Gear | D10: M | E10: =2 -> 2 | F10: pairs | I10: =IF(OR(E10="",H10=""),"",E10*H10) | J10: 19 Sep 2026 - received from Bedaya (transfer) | Transfer 2 pairs; pre-transfer M count QUANTITY NOT WRITTEN (only 'M' listed)
A11: Promenade | B11: Shin Guard | C11: Protective Gear | D11: L | E11: =2+2 -> 4 | F11: pairs | I11: =IF(OR(E11="",H11=""),"",E11*H11) | J11: 19 Sep 2026 - received from Bedaya (transfer) | 2 pairs counted (New items, Sep 16) + 2 pairs transferred
A12: Promenade | B12: Shin Guard | C12: Protective Gear | D12: XL | E12: 2 | F12: pairs | I12: =IF(OR(E12="",H12=""),"",E12*H12) | J12: 19 Sep 2026 - received from Bedaya (transfer)
A13: Promenade | B13: White T-shirt (Elite) | C13: Merchandise | D13: 11/12 | E13: 5 | F13: pcs | I13: =IF(OR(E13="",H13=""),"",E13*H13) | J13: Sep 2026 (16-17) - Promenade handwritten count, before 19 Sep transfer | New Elite T-shirt
A14: Promenade | B14: White T-shirt (Elite) | C14: Merchandise | D14: 9/10 | E14: 6 | F14: pcs | I14: =IF(OR(E14="",H14=""),"",E14*H14) | J14: Sep 2026 (16-17) - Promenade handwritten count, before 19 Sep transfer | New Elite T-shirt
A15: Promenade | B15: White T-shirt (Elite) | C15: Merchandise | D15: 7/8 | E15: 2 | F15: pcs | I15: =IF(OR(E15="",H15=""),"",E15*H15) | J15: Sep 2026 (16-17) - Promenade handwritten count, before 19 Sep transfer | New Elite T-shirt
A16: Promenade | B16: White T-shirt (Elite) | C16: Merchandise | D16: 5/6 | E16: 2 | F16: pcs | I16: =IF(OR(E16="",H16=""),"",E16*H16) | J16: Sep 2026 (16-17) - Promenade handwritten count, before 19 Sep transfer | New Elite T-shirt
A17: Promenade | B17: White T-shirt (Elite) | C17: Merchandise | D17: 3/4 | E17: 8 | F17: pcs | I17: =IF(OR(E17="",H17=""),"",E17*H17) | J17: Sep 2026 (16-17) - Promenade handwritten count, before 19 Sep transfer | New Elite T-shirt
A18: Promenade | B18: White T-shirt (Elite) - From Argan (Old) | C18: Merchandise | D18: 13/14 | E18: 1 | F18: pcs | I18: =IF(OR(E18="",H18=""),"",E18*H18) | J18: Sep 2026 (16-17) - Promenade handwritten count, before 19 Sep transfer | Marked 'From Argan', old - check not already counted at Bedaya
A19: Promenade | B19: White T-shirt (Elite) - From Argan (Old) | C19: Merchandise | D19: 11/12 | E19: 2 | F19: pcs | I19: =IF(OR(E19="",H19=""),"",E19*H19) | J19: Sep 2026 (16-17) - Promenade handwritten count, before 19 Sep transfer | Marked 'From Argan', old - check not already counted at Bedaya
A20: Promenade | B20: White T-shirt (Elite) - From Argan (Old) | C20: Merchandise | D20: 5/6 | E20: 1 | F20: pcs | I20: =IF(OR(E20="",H20=""),"",E20*H20) | J20: Sep 2026 (16-17) - Promenade handwritten count, before 19 Sep transfer | Marked 'From Argan', old - check not already counted at Bedaya
A21: Promenade | B21: White T-shirt (Elite) - From Argan (Old) | C21: Merchandise | D21: 3/4 | E21: 2 | F21: pcs | I21: =IF(OR(E21="",H21=""),"",E21*H21) | J21: Sep 2026 (16-17) - Promenade handwritten count, before 19 Sep transfer | Marked 'From Argan', old - check not already counted at Bedaya
A22: Promenade | B22: Instructor T-shirt (Elite Logo) | C22: Merchandise | D22: L | E22: 1 | F22: pcs | I22: =IF(OR(E22="",H22=""),"",E22*H22) | J22: Sep 2026 (16-17) - Promenade handwritten count, before 19 Sep transfer | New Elite T-shirt, gray, for instructor
A23: Promenade | B23: Elite T-shirt (Gray) | C23: Merchandise | D23: L | E23: 2 | F23: pcs | I23: =IF(OR(E23="",H23=""),"",E23*H23) | J23: Sep 2026 (16-17) - Promenade handwritten count, before 19 Sep transfer | 'New items' page - may overlap with Instructor T-shirt L
... A31: Promenade | B31: Gloves (Elite Logo) - Old | C31: Protective Gear | D31: M | E31: 23 | F31: pairs | I31: =IF(OR(E31="",H31=""),"",E31*H31) | J31: Sep 2026 (16-17) - Promenade handwritten count, before 19 Sep transfer | Old. 23 written beside M only - could be total for L/M/S
A32: Promenade | B32: Gloves (Elite Logo) - Old | C32: Protective Gear | D32: L | F32: pairs | I32: =IF(OR(E32="",H32=""),"",E32*H32) | J32: Sep 2026 (16-17) - Promenade handwritten count, before 19 Sep transfer | Old. QUANTITY NOT WRITTEN (dash)
A33: Promenade | B33: Gloves (Elite Logo) - Old | C33: Protective Gear | D33: S | F33: pairs | I33: =IF(OR(E33="",H33=""),"",E33*H33) | J33: Sep 2026 (16-17) - Promenade handwritten count, before 19 Sep transfer | Old. QUANTITY NOT WRITTEN (dash)
A34: Promenade | B34: Shin Guard (Elite Logo) - Old | C34: Protective Gear | D34: L | E34: 3 | F34: pairs | I34: =IF(OR(E34="",H34=""),"",E34*H34) | J34: Sep 2026 (16-17) - Promenade handwritten count, before 19 Sep transfer | Old
A35: Promenade | B35: Jiu Jitsu Uniform (Elite Logo) | C35: Uniforms | D35: A3 - Black | E35: 1 | F35: pcs | I35: =IF(OR(E35="",H35=""),"",E35*H35) | J35: Sep 2026 (16-17) - Promenade handwritten count, before 19 Sep transfer | With Elite logo; size as written 'A-3'
A36: Promenade | B36: Jiu Jitsu Uniform (Elite Logo) | C36: Uniforms | D36: 3/180 - Gray | E36: 1 | F36: pcs | I36: =IF(OR(E36="",H36=""),"",E36*H36) | J36: Sep 2026 (16-17) - Promenade handwritten count, before 19 Sep transfer | With Elite logo; size as written
A37: Promenade | B37: Jiu Jitsu Uniform (Elite Logo) | C37: Uniforms | D37: A3 - Gray/Blue | E37: 1 | F37: pcs | I37: =IF(OR(E37="",H37=""),"",E37*H37) | J37: Sep 2026 (16-17) - Promenade handwritten count, before 19 Sep transfer | With Elite logo; size as written 'A-3'
A38: Promenade | B38: Systema T-shirt (Black) | C38: Merchandise | D38: L | E38: 5 | F38: pcs | I38: =IF(OR(E38="",H38=""),"",E38*H38) | J38: Sep 2026 (16-17) - Promenade handwritten count, before 19 Sep transfer
A39: Promenade | B39: Systema T-shirt (Black) | C39: Merchandise | D39: M | E39: 2 | F39: pcs | I39: =IF(OR(E39="",H39=""),"",E39*H39) | J39: Sep 2026 (16-17) - Promenade handwritten count, before 19 Sep transfer
A40: Promenade | B40: Systema T-shirt (Black) | C40: Merchandise | D40: S | E40: 15 | F40: pcs | I40: =IF(OR(E40="",H40=""),"",E40*H40) | J40: Sep 2026 (16-17) - Promenade handwritten count, before 19 Sep transfer
A41: Promenade | B41: Systema T-shirt (Black) | C41: Merchandise | D41: 40 | E41: 6 | F41: pcs | I41: =IF(OR(E41="",H41=""),"",E41*H41) | J41: Sep 2026 (16-17) - Promenade handwritten count, before 19 Sep transfer | Numeric sizes 36-40 kept as separate variants
A42: Promenade | B42: Systema T-shirt (Black) | C42: Merchandise | D42: 38 | E42: 19 | F42: pcs | I42: =IF(OR(E42="",H42=""),"",E42*H42) | J42: Sep 2026 (16-17) - Promenade handwritten count, before 19 Sep transfer | Numeric sizes 36-40 kept as separate variants
A43: Promenade | B43: Systema T-shirt (Black) | C43: Merchandise | D43: 36 | E43: 20 | F43: pcs | I43: =IF(OR(E43="",H43=""),"",E43*H43) | J43: Sep 2026 (16-17) - Promenade handwritten count, before 19 Sep transfer | Numeric sizes 36-40 kept as separate variants
A44: Promenade | B44: Systema T-shirt (Gray) | C44: Merchandise | D44: 3XL | E44: 2 | F44: pcs | I44: =IF(OR(E44="",H44=""),"",E44*H44) | J44: Sep 2026 (16-17) - Promenade handwritten count, before 19 Sep transfer
A45: Promenade | B45: Systema T-shirt (Gray) | C45: Merchandise | D45: XXL | E45: 3 | F45: pcs | I45: =IF(OR(E45="",H45=""),"",E45*H45) | J45: Sep 2026 (16-17) - Promenade handwritten count, before 19 Sep transfer | XXL: 2 crossed out, 3 written
... A48: Promenade | B48: Systema T-shirt (Gray) | C48: Merchandise | D48: M | E48: 2 | F48: pcs | I48: =IF(OR(E48="",H48=""),"",E48*H48) | J48: Sep 2026 (16-17) - Promenade handwritten count, before 19 Sep transfer
A49: Promenade | B49: Systema T-shirt (Gray) | C49: Merchandise | D49: S | F49: pcs | I49: =IF(OR(E49="",H49=""),"",E49*H49) | J49: Sep 2026 (16-17) - Promenade handwritten count, before 19 Sep transfer | QUANTITY NOT WRITTEN (dash)
...

Sheet Bedaya
A1: Branch | B1: Item name | C1: Category | D1: Size / Variant | E1: Quantity counted | F1: Unit | G1: Reorder level | H1: Unit cost | I1: Total value | J1: Notes
A2: Bedaya | B2: Kyokushin Gloves (White) | C2: Protective Gear | D2: Small | E2: 1 | F2: pairs | I2: =IF(OR(E2="",H2=""),"",E2*H2) | J2: 17 Sep 2026 - floor count
A3: Bedaya | B3: Kyokushin Gloves (White) | C3: Protective Gear | D3: XS | E3: 2 | F3: pairs | I3: =IF(OR(E3="",H3=""),"",E3*H3) | J3: 17 Sep 2026 - floor count
A4: Bedaya | B4: Mouth Guard | C4: Protective Gear | D4: Small | E4: 2 | F4: pcs | I4: =IF(OR(E4="",H4=""),"",E4*H4) | J4: 17 Sep 2026 - floor count
A5: Bedaya | B5: Mouth Guard | C5: Protective Gear | D5: Junior | E5: 12 | F5: pcs | I5: =IF(OR(E5="",H5=""),"",E5*H5) | J5: 17 Sep 2026 - floor count
A6: Bedaya | B6: Supporter | C6: Protective Gear | D6: M | E6: 7 | F6: pcs | I6: =IF(OR(E6="",H6=""),"",E6*H6) | J6: 17 Sep 2026 - floor count | Assumed groin guard - confirm name
A7: Bedaya | B7: Supporter | C7: Protective Gear | D7: S | E7: 9 | F7: pcs | I7: =IF(OR(E7="",H7=""),"",E7*H7) | J7: 17 Sep 2026 - floor count | Assumed groin guard - confirm name
A8: Bedaya | B8: Kickboxing T-shirt | C8: Merchandise | D8: XL | E8: 2 | F8: pcs | I8: =IF(OR(E8="",H8=""),"",E8*H8) | J8: 17 Sep 2026 - floor count
A9: Bedaya | B9: Kickboxing T-shirt | C9: Merchandise | D9: L | E9: 3 | F9: pcs | I9: =IF(OR(E9="",H9=""),"",E9*H9) | J9: 17 Sep 2026 - floor count
A10: Bedaya | B10: Kickboxing T-shirt | C10: Merchandise | D10: M | E10: 0 | F10: pcs | I10: =IF(OR(E10="",H10=""),"",E10*H10) | J10: 17 Sep 2026 - floor count | OUT OF STOCK - reorder
A11: Bedaya | B11: Kickboxing T-shirt | C11: Merchandise | D11: S | E11: 0 | F11: pcs | I11: =IF(OR(E11="",H11=""),"",E11*H11) | J11: 17 Sep 2026 - floor count | OUT OF STOCK - reorder
A12: Bedaya | B12: Kickboxing T-shirt | C12: Merchandise | D12: 40 | E12: 2 | F12: pcs | I12: =IF(OR(E12="",H12=""),"",E12*H12) | J12: 17 Sep 2026 - floor count | Numeric size
A13: Bedaya | B13: Kickboxing T-shirt | C13: Merchandise | D13: 38 | E13: 1 | F13: pcs | I13: =IF(OR(E13="",H13=""),"",E13*H13) | J13: 17 Sep 2026 - floor count | Numeric size
... A63: Bedaya | B63: Elite MMA T-shirt | C63: Merchandise | D63: S | E63: 1 | F63: pcs | I63: =IF(OR(E63="",H63=""),"",E63*H63) | J63: 17 Sep 2026 - store / old stock
A64: Bedaya | B64: Shin Guard | C64: Protective Gear | D64: XL | E64: =1-2 -> -1 | F64: pairs | I64: =IF(OR(E64="",H64=""),"",E64*H64) | J64: 20 Sep 2026 - stock remaining | Count 1 less 2 transferred to Promenade 19 Sep 2026
A65: Bedaya | B65: Shin Guard | C65: Protective Gear | D65: L | E65: =2-2 -> 0 | F65: pairs | I65: =IF(OR(E65="",H65=""),"",E65*H65) | J65: 20 Sep 2026 - stock remaining | Count 2 less 2 transferred to Promenade 19 Sep 2026
A66: Bedaya | B66: Shin Guard | C66: Protective Gear | D66: M | E66: =1-2 -> -1 | F66: pairs | I66: =IF(OR(E66="",H66=""),"",E66*H66) | J66: 20 Sep 2026 - stock remaining | Count 1 less 2 transferred to Promenade 19 Sep 2026
A67: Bedaya | B67: Shin Guard | C67: Protective Gear | D67: S | E67: =1-1 -> 0 | F67: pairs | I67: =IF(OR(E67="",H67=""),"",E67*H67) | J67: 20 Sep 2026 - stock remaining | Count 1 less 1 transferred to Promenade 19 Sep 2026
A68: Bedaya | B68: Shin Guard | C68: Protective Gear | D68: XS | E68: =2-2 -> 0 | F68: pairs | I68: =IF(OR(E68="",H68=""),"",E68*H68) | J68: 20 Sep 2026 - stock remaining | Count 2 less 2 transferred to Promenade 19 Sep 2026
A69: Bedaya | B69: Boxing Gloves | C69: Protective Gear | D69: 12oz | E69: =1-1 -> 0 | F69: pairs | I69: =IF(OR(E69="",H69=""),"",E69*H69) | J69: 20 Sep 2026 - stock remaining | Count 1 less 1 transferred to Promenade 19 Sep 2026
A70: Bedaya | B70: Boxing Gloves | C70: Protective Gear | D70: 10oz | E70: =2-2 -> 0 | F70: pairs | I70: =IF(OR(E70="",H70=""),"",E70*H70) | J70: 20 Sep 2026 - stock remaining | Count 2 less 2 transferred to Promenade 19 Sep 2026
A71: Bedaya | B71: Boxing Gloves | C71: Protective Gear | D71: 8oz | E71: =3-2 -> 1 | F71: pairs | I71: =IF(OR(E71="",H71=""),"",E71*H71) | J71: 20 Sep 2026 - stock remaining | Count 3 less 2 transferred to Promenade 19 Sep 2026
A72: Bedaya | B72: Boxing Gloves | C72: Protective Gear | D72: 6oz | E72: =1-2 -> -1 | F72: pairs | I72: =IF(OR(E72="",H72=""),"",E72*H72) | J72: 20 Sep 2026 - stock remaining | Count 1 less 2 transferred to Promenade 19 Sep 2026
A73: Bedaya | B73: Boxing Gloves | C73: Protective Gear | D73: 4oz | E73: 3 | F73: pairs | I73: =IF(OR(E73="",H73=""),"",E73*H73) | J73: 20 Sep 2026 - stock remaining
A74: Bedaya | B74: Boxing Gloves | C74: Protective Gear | D74: 2oz | E74: 2 | F74: pairs | I74: =IF(OR(E74="",H74=""),"",E74*H74) | J74: 20 Sep 2026 - stock remaining
A75: Bedaya | B75: UFC Gloves | C75: Protective Gear | D75: 8oz | E75: 3 | F75: pairs | I75: =IF(OR(E75="",H75=""),"",E75*H75) | J75: 20 Sep 2026 - stock remaining
A76: Bedaya | B76: Kajukimbo Patch - Circle (Front) | C76: Patches & Badges | D76: - | E76: 25 | F76: pcs | I76: =IF(OR(E76="",H76=""),"",E76*H76) | J76: 20 Sep 2026 - stock remaining
A77: Bedaya | B77: Kajukimbo Patch - Shoulder | C77: Patches & Badges | D77: - | E77: 26 | F77: pcs | I77: =IF(OR(E77="",H77=""),"",E77*H77) | J77: 20 Sep 2026 - stock remaining | Unit not written - assumed pcs
I78: =IF(OR(E78="",H78=""),"",E78*H78)
I79: =IF(OR(E79="",H79=""),"",E79*H79)
I80: =IF(OR(E80="",H80=""),"",E80*H80)
I81: =IF(OR(E81="",H81=""),"",E81*H81)
I82: =IF(OR(E82="",H82=""),"",E82*H82)
I83: =IF(OR(E83="",H83=""),"",E83*H83)
I84: =IF(OR(E84="",H84=""),"",E84*H84)
I85: =IF(OR(E85="",H85=""),"",E85*H85)
I86: =IF(OR(E86="",H86=""),"",E86*H86)
I87: =IF(OR(E87="",H87=""),"",E87*H87)
I88: =IF(OR(E88="",H88=""),"",E88*H88)
I89: =IF(OR(E89="",H89=""),"",E89*H89)
...

Sheet Bedaya vs Mindbody
A1: Bedaya - physical count vs Mindbody (Inventory On Hand, 20 Sep 2026)
A2: Physical counts are 17 and 20 Sep 2026; sales between count date and 20 Sep are NOT adjusted. Mindbody quantities (blue) are typed from the export.
A4: Summary (number of lines)
A5: Match | C5: Physical higher | E5: Mindbody higher | G5: Not in Mindbody | I5: Not counted
A6: =COUNTIF($H$10:$H$128,"Match") -> 57 | C6: =COUNTIF($H$10:$H$128,"Physical higher") -> 4 | E6: =COUNTIF($H$10:$H$128,"Mindbody higher") -> 11 | G6: =COUNTIF($H$10:$H$128,"Not in Mindbody") -> 23 | I6: =COUNTIF($H$10:$H$128,"Not counted") -> 24
A9: Mindbody product | B9: Mindbody size | C9: Counted item | D9: Counted size | E9: Physical count | F9: Mindbody qty | G9: Variance (physical - Mindbody) | H9: Status | I9: Comment
A10: Boxing Gloves | B10: 2 oz | C10: Boxing Gloves | D10: 2oz | E10: =SUMPRODUCT((Bedaya!$B$2:$B$200="Boxing Gloves")*(Bedaya!$D$2:$D$200="2oz"),Bedaya!$E$2:$E$200) -> 2 | F10: 2 | G10: =IF(OR(E10="",F10=""),"",E10-F10) -> 0 | H10: =IF(E10="","Not counted",IF(F10="","Not in Mindbody",IF(E10=F10,"Match",IF(E10>F10,"Physical higher","Mindbody higher")))) -> Match | I10: Physical reduced by pairs transferred to Promenade on 19 Sep; Mindbody quantity not adjusted.
A11: Boxing Gloves | B11: 4 oz | C11: Boxing Gloves | D11: 4oz | E11: =SUMPRODUCT((Bedaya!$B$2:$B$200="Boxing Gloves")*(Bedaya!$D$2:$D$200="4oz"),Bedaya!$E$2:$E$200) -> 3 | F11: 3 | G11: =IF(OR(E11="",F11=""),"",E11-F11) -> 0 | H11: =IF(E11="","Not counted",IF(F11="","Not in Mindbody",IF(E11=F11,"Match",IF(E11>F11,"Physical higher","Mindbody higher")))) -> Match | I11: Physical reduced by pairs transferred to Promenade on 19 Sep; Mindbody quantity not adjusted.
A12: Boxing Gloves | B12: 6 oz | C12: Boxing Gloves | D12: 6oz | E12: =SUMPRODUCT((Bedaya!$B$2:$B$200="Boxing Gloves")*(Bedaya!$D$2:$D$200="6oz"),Bedaya!$E$2:$E$200) -> -1 | F12: 1 | G12: =IF(OR(E12="",F12=""),"",E12-F12) -> -2 | H12: =IF(E12="","Not counted",IF(F12="","Not in Mindbody",IF(E12=F12,"Match",IF(E12>F12,"Physical higher","Mindbody higher")))) -> Mindbody higher | I12: Physical reduced by pairs transferred to Promenade on 19 Sep; Mindbody quantity not adjusted.
A13: Boxing Gloves | B13: 8 oz | C13: Boxing Gloves | D13: 8oz | E13: =SUMPRODUCT((Bedaya!$B$2:$B$200="Boxing Gloves")*(Bedaya!$D$2:$D$200="8oz"),Bedaya!$E$2:$E$200) -> 1 | F13: 3 | G13: =IF(OR(E13="",F13=""),"",E13-F13) -> -2 | H13: =IF(E13="","Not counted",IF(F13="","Not in Mindbody",IF(E13=F13,"Match",IF(E13>F13,"Physical higher","Mindbody higher")))) -> Mindbody higher | I13: Physical reduced by pairs transferred to Promenade on 19 Sep; Mindbody quantity not adjusted.
A14: Boxing Gloves | B14: 10 oz | C14: Boxing Gloves | D14: 10oz | E14: =SUMPRODUCT((Bedaya!$B$2:$B$200="Boxing Gloves")*(Bedaya!$D$2:$D$200="10oz"),Bedaya!$E$2:$E$200) -> 0 | F14: 2 | G14: =IF(OR(E14="",F14=""),"",E14-F14) -> -2 | H14: =IF(E14="","Not counted",IF(F14="","Not in Mindbody",IF(E14=F14,"Match",IF(E14>F14,"Physical higher","Mindbody higher")))) -> Mindbody higher | I14: Physical reduced by pairs transferred to Promenade on 19 Sep; Mindbody quantity not adjusted.
A15: Boxing Gloves | B15: 12 oz | C15: Boxing Gloves | D15: 12oz | E15: =SUMPRODUCT((Bedaya!$B$2:$B$200="Boxing Gloves")*(Bedaya!$D$2:$D$200="12oz"),Bedaya!$E$2:$E$200) -> 0 | F15: 11 | G15: =IF(OR(E15="",F15=""),"",E15-F15) -> -11 | H15: =IF(E15="","Not counted",IF(F15="","Not in Mindbody",IF(E15=F15,"Match",IF(E15>F15,"Physical higher","Mindbody higher")))) -> Mindbody higher | I15: Physical reduced by pairs transferred to Promenade on 19 Sep; Mindbody quantity not adjusted. Mindbody shows 11 vs 1 counted - recount / check for typo or unadjusted transfer
A16: Boys Protective Gear | B16: (none) | F16: 16 | G16: =IF(OR(E16="",F16=""),"",E16-F16) | H16: =IF(E16="","Not counted",IF(F16="","Not in Mindbody",IF(E16=F16,"Match",IF(E16>F16,"Physical higher","Mindbody higher")))) -> Not counted | I16: In Mindbody, not counted in store
A17: Elite Bag | B17: One Size | C17: Backpack with Elite Logo | D17: - | E17: =SUMPRODUCT((Bedaya!$B$2:$B$200="Backpack with Elite Logo")*(Bedaya!$D$2:$D$200="-"),Bedaya!$E$2:$E$200) -> 9 | F17: 9 | G17: =IF(OR(E17="",F17=""),"",E17-F17) -> 0 | H17: =IF(E17="","Not counted",IF(F17="","Not in Mindbody",IF(E17=F17,"Match",IF(E17>F17,"Physical higher","Mindbody higher")))) -> Match
A18: Elite Jacket | B18: Large | F18: 1 | G18: =IF(OR(E18="",F18=""),"",E18-F18) | H18: =IF(E18="","Not counted",IF(F18="","Not in Mindbody",IF(E18=F18,"Match",IF(E18>F18,"Physical higher","Mindbody higher")))) -> Not counted | I18: In Mindbody, not counted in store
A19: Elite Shirt (Black) | B19: (none) | F19: 7 | G19: =IF(OR(E19="",F19=""),"",E19-F19) | H19: =IF(E19="","Not counted",IF(F19="","Not in Mindbody",IF(E19=F19,"Match",IF(E19>F19,"Physical higher","Mindbody higher")))) -> Not counted | I19: In Mindbody, not counted in store
A20: Elite Shirt (White) | B20: 3 - 4 | C20: White T-shirt (Elite) | D20: 3/4 | E20: =SUMPRODUCT((Bedaya!$B$2:$B$200="White T-shirt (Elite)")*(Bedaya!$D$2:$D$200="3/4"),Bedaya!$E$2:$E$200) -> 7 | F20: 7 | G20: =IF(OR(E20="",F20=""),"",E20-F20) -> 0 | H20: =IF(E20="","Not counted",IF(F20="","Not in Mindbody",IF(E20=F20,"Match",IF(E20>F20,"Physical higher","Mindbody higher")))) -> Match
A21: Elite Shirt (White) | B21: 5 - 6 | C21: White T-shirt (Elite) | D21: 5/6 | E21: =SUMPRODUCT((Bedaya!$B$2:$B$200="White T-shirt (Elite)")*(Bedaya!$D$2:$D$200="5/6"),Bedaya!$E$2:$E$200) -> 9 | F21: 9 | G21: =IF(OR(E21="",F21=""),"",E21-F21) -> 0 | H21: =IF(E21="","Not counted",IF(F21="","Not in Mindbody",IF(E21=F21,"Match",IF(E21>F21,"Physical higher","Mindbody higher")))) -> Match
A22: Elite Shirt (White) | B22: 11 - 12 | C22: White T-shirt (Elite) | D22: 11/12 | E22: =SUMPRODUCT((Bedaya!$B$2:$B$200="White T-shirt (Elite)")*(Bedaya!$D$2:$D$200="11/12"),Bedaya!$E$2:$E$200) -> 3 | F22: 3 | G22: =IF(OR(E22="",F22=""),"",E22-F22) -> 0 | H22: =IF(E22="","Not counted",IF(F22="","Not in Mindbody",IF(E22=F22,"Match",IF(E22>F22,"Physical higher","Mindbody higher")))) -> Match
A23: Elite Shirt (White) | B23: 13 - 14 | C23: White T-shirt (Elite) | D23: 13/14 | E23: =SUMPRODUCT((Bedaya!$B$2:$B$200="White T-shirt (Elite)")*(Bedaya!$D$2:$D$200="13/14"),Bedaya!$E$2:$E$200) -> 4 | F23: 4 | G23: =IF(OR(E23="",F23=""),"",E23-F23) -> 0 | H23: =IF(E23="","Not counted",IF(F23="","Not in Mindbody",IF(E23=F23,"Match",IF(E23>F23,"Physical higher","Mindbody higher")))) -> Match
A24: Elite Shirt (White) | B24: Large | C24: Students' Elite T-shirt (White) | D24: L | E24: =SUMPRODUCT((Bedaya!$B$2:$B$200="Students' Elite T-shirt (White)")*(Bedaya!$D$2:$D$200="L"),Bedaya!$E$2:$E$200) -> 6 | F24: 6 | G24: =IF(OR(E24="",F24=""),"",E24-F24) -> 0 | H24: =IF(E24="","Not counted",IF(F24="","Not in Mindbody",IF(E24=F24,"Match",IF(E24>F24,"Physical higher","Mindbody higher")))) -> Match
A25: Elite Shirt (White) | B25: Medium | C25: Students' Elite T-shirt (White) | D25: M | E25: =SUMPRODUCT((Bedaya!$B$2:$B$200="Students' Elite T-shirt (White)")*(Bedaya!$D$2:$D$200="M"),Bedaya!$E$2:$E$200) -> 1 | F25: 1 | G25: =IF(OR(E25="",F25=""),"",E25-F25) -> 0 | H25: =IF(E25="","Not counted",IF(F25="","Not in Mindbody",IF(E25=F25,"Match",IF(E25>F25,"Physical higher","Mindbody higher")))) -> Match
A26: Elite Shirt (White) | B26: X Large | F26: 2 | G26: =IF(OR(E26="",F26=""),"",E26-F26) | H26: =IF(E26="","Not counted",IF(F26="","Not in Mindbody",IF(E26=F26,"Match",IF(E26>F26,"Physical higher","Mindbody higher")))) -> Not counted | I26: In Mindbody, not counted in store
A27: Elite Shirt (White) | B27: 9 - 10 | F27: -3 | G27: =IF(OR(E27="",F27=""),"",E27-F27) | H27: =IF(E27="","Not counted",IF(F27="","Not in Mindbody",IF(E27=F27,"Match",IF(E27>F27,"Physical higher","Mindbody higher")))) -> Not counted | I27: NEGATIVE stock in Mindbody - adjust
A28: Elite Tournament | B28: (none) | F28: -1 | G28: =IF(OR(E28="",F28=""),"",E28-F28) | H28: =IF(E28="","Not counted",IF(F28="","Not in Mindbody",IF(E28=F28,"Match",IF(E28>F28,"Physical higher","Mindbody higher")))) -> Not counted | I28: Event/service item with negative stock - not a physical item
A29: Free Belts | B29: Black | F29: 1 | G29: =IF(OR(E29="",F29=""),"",E29-F29) | H29: =IF(E29="","Not counted",IF(F29="","Not in Mindbody",IF(E29=F29,"Match",IF(E29>F29,"Physical higher","Mindbody higher")))) -> Not counted | I29: In Mindbody, not counted in store
A30: Free Belts | B30: Blue | F30: 16 | G30: =IF(OR(E30="",F30=""),"",E30-F30) | H30: =IF(E30="","Not counted",IF(F30="","Not in Mindbody",IF(E30=F30,"Match",IF(E30>F30,"Physical higher","Mindbody higher")))) -> Not counted | I30: In Mindbody, not counted in store
A31: Free Belts | B31: Brown | F31: 7 | G31: =IF(OR(E31="",F31=""),"",E31-F31) | H31: =IF(E31="","Not counted",IF(F31="","Not in Mindbody",IF(E31=F31,"Match",IF(E31>F31,"Physical higher","Mindbody higher")))) -> Not counted | I31: In Mindbody, not counted in store
A32: Free Belts | B32: Green | F32: 16 | G32: =IF(OR(E32="",F32=""),"",E32-F32) | H32: =IF(E32="","Not counted",IF(F32="","Not in Mindbody",IF(E32=F32,"Match",IF(E32>F32,"Physical higher","Mindbody higher")))) -> Not counted | I32: In Mindbody, not counted in store
A33: Free Belts | B33: Orange | F33: 25 | G33: =IF(OR(E33="",F33=""),"",E33-F33) | H33: =IF(E33="","Not counted",IF(F33="","Not in Mindbody",IF(E33=F33,"Match",IF(E33>F33,"Physical higher","Mindbody higher")))) -> Not counted | I33: In Mindbody, not counted in store
A34: Free Belts | B34: Purple | F34: 31 | G34: =IF(OR(E34="",F34=""),"",E34-F34) | H34: =IF(E34="","Not counted",IF(F34="","Not in Mindbody",IF(E34=F34,"Match",IF(E34>F34,"Physical higher","Mindbody higher")))) -> Not counted | I34: In Mindbody, not counted in store
A35: Free Belts | B35: Red | F35: 21 | G35: =IF(OR(E35="",F35=""),"",E35-F35) | H35: =IF(E35="","Not counted",IF(F35="","Not in Mindbody",IF(E35=F35,"Match",IF(E35>F35,"Physical higher","Mindbody higher")))) -> Not counted | I35: In Mindbody, not counted in store
A36: Free Belts | B36: Yellow | F36: 20 | G36: =IF(OR(E36="",F36=""),"",E36-F36) | H36: =IF(E36="","Not counted",IF(F36="","Not in Mindbody",IF(E36=F36,"Match",IF(E36>F36,"Physical higher","Mindbody higher")))) -> Not counted | I36: In Mindbody, not counted in store
A37: Instructor Shirt | B37: (no XL / L line) | C37: Instructor T-shirt (Elite Logo) | D37: XL | E37: =SUMPRODUCT((Bedaya!$B$2:$B$200="Instructor T-shirt (Elite Logo)")*(Bedaya!$D$2:$D$200="XL"),Bedaya!$E$2:$E$200) -> 3 | G37: =IF(OR(E37="",F37=""),"",E37-F37) | H37: =IF(E37="","Not counted",IF(F37="","Not in Mindbody",IF(E37=F37,"Match",IF(E37>F37,"Physical higher","Mindbody higher")))) -> Not in Mindbody | I37: Mindbody only has Grey S and XXL (both 0)
A38: Instructor Shirt | B38: (no XL / L line) | C38: Instructor T-shirt (Elite Logo) | D38: L | E38: =SUMPRODUCT((Bedaya!$B$2:$B$200="Instructor T-shirt (Elite Logo)")*(Bedaya!$D$2:$D$200="L"),Bedaya!$E$2:$E$200) -> 1 | G38: =IF(OR(E38="",F38=""),"",E38-F38) | H38: =IF(E38="","Not counted",IF(F38="","Not in Mindbody",IF(E38=F38,"Match",IF(E38>F38,"Physical higher","Mindbody higher")))) -> Not in Mindbody | I38: Mindbody only has Grey S and XXL (both 0)
A39: Kajukenbo Patch | B39: (one line for both patches) | C39: Kajukimbo Patch - Circle (Front) + Kajukimbo Patch - Shoulder | D39: - + - | E39: =SUMPRODUCT((Bedaya!$B$2:$B$200="Kajukimbo Patch - Circle (Front)")*(Bedaya!$D$2:$D$200="-"),Bedaya!$E$2:$E$200)+SUMPRODUCT((Bedaya!$B$2:$B$200="Kajukimbo Patch - Shoulder")*(Bedaya!$D$2:$D$200="-"),Bedaya!$E$2:$E$200) -> 51 | F39: 62 | G39: =IF(OR(E39="",F39=""),"",E39-F39) -> -11 | H39: =IF(E39="","Not counted",IF(F39="","Not in Mindbody",IF(E39=F39,"Match",IF(E39>F39,"Physical higher","Mindbody higher")))) -> Mindbody higher | I39: Circle 25 + Shoulder 26 compared with the single Mindbody line (Promenade patches excluded)
A40: Kajukenbo Uniform w/ Patches | B40: 100 | C40: Kajukimbo Uniform | D40: 100cm | E40: =SUMPRODUCT((Bedaya!$B$2:$B$200="Kajukimbo Uniform")*(Bedaya!$D$2:$D$200="100cm"),Bedaya!$E$2:$E$200) -> 5 | F40: 5 | G40: =IF(OR(E40="",F40=""),"",E40-F40) -> 0 | H40: =IF(E40="","Not counted",IF(F40="","Not in Mindbody",IF(E40=F40,"Match",IF(E40>F40,"Physical higher","Mindbody higher")))) -> Match
A41: Kajukenbo Uniform w/ Patches | B41: 110 | C41: Kajukimbo Uniform | D41: 110cm | E41: =SUMPRODUCT((Bedaya!$B$2:$B$200="Kajukimbo Uniform")*(Bedaya!$D$2:$D$200="110cm"),Bedaya!$E$2:$E$200) -> 4 | F41: 4 | G41: =IF(OR(E41="",F41=""),"",E41-F41) -> 0 | H41: =IF(E41="","Not counted",IF(F41="","Not in Mindbody",IF(E41=F41,"Match",IF(E41>F41,"Physical higher","Mindbody higher")))) -> Match
A42: Kajukenbo Uniform w/ Patches | B42: 120 | C42: Kajukimbo Uniform | D42: 120cm | E42: =SUMPRODUCT((Bedaya!$B$2:$B$200="Kajukimbo Uniform")*(Bedaya!$D$2:$D$200="120cm"),Bedaya!$E$2:$E$200) -> 0 | F42: 0 | G42: =IF(OR(E42="",F42=""),"",E42-F42) -> 0 | H42: =IF(E42="","Not counted",IF(F42="","Not in Mindbody",IF(E42=F42,"Match",IF(E42>F42,"Physical higher","Mindbody higher")))) -> Match
A43: Kajukenbo Uniform w/ Patches | B43: 130 | C43: Kajukimbo Uniform | D43: 130cm | E43: =SUMPRODUCT((Bedaya!$B$2:$B$200="Kajukimbo Uniform")*(Bedaya!$D$2:$D$200="130cm"),Bedaya!$E$2:$E$200) -> 1 | F43: 1 | G43: =IF(OR(E43="",F43=""),"",E43-F43) -> 0 | H43: =IF(E43="","Not counted",IF(F43="","Not in Mindbody",IF(E43=F43,"Match",IF(E43>F43,"Physical higher","Mindbody higher")))) -> Match
...

Sheet Bedaya Variances
A1: Bedaya - items that do not match Mindbody (20 Sep 2026 export)
A2: Rows link to the 'Bedaya vs Mindbody' tab. Variance = physical - Mindbody. Sorted by status; sales after the count dates are not adjusted.
A4: Physical higher | C4: Mindbody higher | E4: Not in Mindbody | G4: Not counted
A5: =COUNTIF($A$8:$A$300,"Physical higher") -> 4 | C5: =COUNTIF($A$8:$A$300,"Mindbody higher") -> 11 | E5: =COUNTIF($A$8:$A$300,"Not in Mindbody") -> 23 | G5: =COUNTIF($A$8:$A$300,"Not counted") -> 24
A7: Status | B7: Mindbody product | C7: Mindbody size | D7: Counted item | E7: Counted size | F7: Physical count | G7: Mindbody qty | H7: Variance | I7: Comment
A8: =IF('Bedaya vs Mindbody'!H70="","",'Bedaya vs Mindbody'!H70) -> Physical higher | B8: =IF('Bedaya vs Mindbody'!A70="","",'Bedaya vs Mindbody'!A70) -> New Judo | C8: =IF('Bedaya vs Mindbody'!B70="","",'Bedaya vs Mindbody'!B70) -> 100 | D8: =IF('Bedaya vs Mindbody'!C70="","",'Bedaya vs Mindbody'!C70) -> Judo Uniform | E8: =IF('Bedaya vs Mindbody'!D70="","",'Bedaya vs Mindbody'!D70) -> 100cm | F8: =IF('Bedaya vs Mindbody'!E70="","",'Bedaya vs Mindbody'!E70) -> 9 | G8: =IF('Bedaya vs Mindbody'!F70="","",'Bedaya vs Mindbody'!F70) -> 8 | H8: =IF('Bedaya vs Mindbody'!G70="","",'Bedaya vs Mindbody'!G70) -> 1 | I8: =IF('Bedaya vs Mindbody'!I70="","",'Bedaya vs Mindbody'!I70) -> Judo - No Program tab (physical 9 vs 8)
A9: =IF('Bedaya vs Mindbody'!H83="","",'Bedaya vs Mindbody'!H83) -> Physical higher | B9: =IF('Bedaya vs Mindbody'!A83="","",'Bedaya vs Mindbody'!A83) -> New Karate | C9: =IF('Bedaya vs Mindbody'!B83="","",'Bedaya vs Mindbody'!B83) -> 150 | D9: =IF('Bedaya vs Mindbody'!C83="","",'Bedaya vs Mindbody'!C83) -> Karate Uniform | E9: =IF('Bedaya vs Mindbody'!D83="","",'Bedaya vs Mindbody'!D83) -> 150cm | F9: =IF('Bedaya vs Mindbody'!E83="","",'Bedaya vs Mindbody'!E83) -> 4 | G9: =IF('Bedaya vs Mindbody'!F83="","",'Bedaya vs Mindbody'!F83) -> 2 | H9: =IF('Bedaya vs Mindbody'!G83="","",'Bedaya vs Mindbody'!G83) -> 2 | I9: =IF('Bedaya vs Mindbody'!I83="","",'Bedaya vs Mindbody'!I83) -> Mindbody 150 = 2 (the '150 / 160' line is 0)
A10: =IF('Bedaya vs Mindbody'!H84="","",'Bedaya vs Mindbody'!H84) -> Physical higher | B10: =IF('Bedaya vs Mindbody'!A84="","",'Bedaya vs Mindbody'!A84) -> New Karate | C10: =IF('Bedaya vs Mindbody'!B84="","",'Bedaya vs Mindbody'!B84) -> 160 | D10: =IF('Bedaya vs Mindbody'!C84="","",'Bedaya vs Mindbody'!C84) -> Karate Uniform | E10: =IF('Bedaya vs Mindbody'!D84="","",'Bedaya vs Mindbody'!D84) -> 160cm | F10: =IF('Bedaya vs Mindbody'!E84="","",'Bedaya vs Mindbody'!E84) -> 4 | G10: =IF('Bedaya vs Mindbody'!F84="","",'Bedaya vs Mindbody'!F84) -> 3 | H10: =IF('Bedaya vs Mindbody'!G84="","",'Bedaya vs Mindbody'!G84) -> 1 | I10: =IF('Bedaya vs Mindbody'!I84="","",'Bedaya vs Mindbody'!I84)
A11: =IF('Bedaya vs Mindbody'!H108="","",'Bedaya vs Mindbody'!H108) -> Physical higher | B11: =IF('Bedaya vs Mindbody'!A108="","",'Bedaya vs Mindbody'!A108) -> Systema Shirt | C11: =IF('Bedaya vs Mindbody'!B108="","",'Bedaya vs Mindbody'!B108) -> Grey X Large | D11: =IF('Bedaya vs Mindbody'!C108="","",'Bedaya vs Mindbody'!C108) -> Systema T-shirt (Gray) | E11: =IF('Bedaya vs Mindbody'!D108="","",'Bedaya vs Mindbody'!D108) -> XL | F11: =IF('Bedaya vs Mindbody'!E108="","",'Bedaya vs Mindbody'!E108) -> 1 | G11: =IF('Bedaya vs Mindbody'!F108="","",'Bedaya vs Mindbody'!F108) -> 0 | H11: =IF('Bedaya vs Mindbody'!G108="","",'Bedaya vs Mindbody'!G108) -> 1 | I11: =IF('Bedaya vs Mindbody'!I108="","",'Bedaya vs Mindbody'!I108)
A12: =IF('Bedaya vs Mindbody'!H12="","",'Bedaya vs Mindbody'!H12) -> Mindbody higher | B12: =IF('Bedaya vs Mindbody'!A12="","",'Bedaya vs Mindbody'!A12) -> Boxing Gloves | C12: =IF('Bedaya vs Mindbody'!B12="","",'Bedaya vs Mindbody'!B12) -> 6 oz | D12: =IF('Bedaya vs Mindbody'!C12="","",'Bedaya vs Mindbody'!C12) -> Boxing Gloves | E12: =IF('Bedaya vs Mindbody'!D12="","",'Bedaya vs Mindbody'!D12) -> 6oz | F12: =IF('Bedaya vs Mindbody'!E12="","",'Bedaya vs Mindbody'!E12) -> -1 | G12: =IF('Bedaya vs Mindbody'!F12="","",'Bedaya vs Mindbody'!F12) -> 1 | H12: =IF('Bedaya vs Mindbody'!G12="","",'Bedaya vs Mindbody'!G12) -> -2 | I12: =IF('Bedaya vs Mindbody'!I12="","",'Bedaya vs Mindbody'!I12) -> Physical reduced by pairs transferred to Promenade on 19 Sep; Mindbody quantity not adjusted.
A13: =IF('Bedaya vs Mindbody'!H13="","",'Bedaya vs Mindbody'!H13) -> Mindbody higher | B13: =IF('Bedaya vs Mindbody'!A13="","",'Bedaya vs Mindbody'!A13) -> Boxing Gloves | C13: =IF('Bedaya vs Mindbody'!B13="","",'Bedaya vs Mindbody'!B13) -> 8 oz | D13: =IF('Bedaya vs Mindbody'!C13="","",'Bedaya vs Mindbody'!C13) -> Boxing Gloves | E13: =IF('Bedaya vs Mindbody'!D13="","",'Bedaya vs Mindbody'!D13) -> 8oz | F13: =IF('Bedaya vs Mindbody'!E13="","",'Bedaya vs Mindbody'!E13) -> 1 | G13: =IF('Bedaya vs Mindbody'!F13="","",'Bedaya vs Mindbody'!F13) -> 3 | H13: =IF('Bedaya vs Mindbody'!G13="","",'Bedaya vs Mindbody'!G13) -> -2 | I13: =IF('Bedaya vs Mindbody'!I13="","",'Bedaya vs Mindbody'!I13) -> Physical reduced by pairs transferred to Promenade on 19 Sep; Mindbody quantity not adjusted.
A14: =IF('Bedaya vs Mindbody'!H14="","",'Bedaya vs Mindbody'!H14) -> Mindbody higher | B14: =IF('Bedaya vs Mindbody'!A14="","",'Bedaya vs Mindbody'!A14) -> Boxing Gloves | C14: =IF('Bedaya vs Mindbody'!B14="","",'Bedaya vs Mindbody'!B14) -> 10 oz | D14: =IF('Bedaya vs Mindbody'!C14="","",'Bedaya vs Mindbody'!C14) -> Boxing Gloves | E14: =IF('Bedaya vs Mindbody'!D14="","",'Bedaya vs Mindbody'!D14) -> 10oz | F14: =IF('Bedaya vs Mindbody'!E14="","",'Bedaya vs Mindbody'!E14) -> 0 | G14: =IF('Bedaya vs Mindbody'!F14="","",'Bedaya vs Mindbody'!F14) -> 2 | H14: =IF('Bedaya vs Mindbody'!G14="","",'Bedaya vs Mindbody'!G14) -> -2 | I14: =IF('Bedaya vs Mindbody'!I14="","",'Bedaya vs Mindbody'!I14) -> Physical reduced by pairs transferred to Promenade on 19 Sep; Mindbody quantity not adjusted.
A15: =IF('Bedaya vs Mindbody'!H15="","",'Bedaya vs Mindbody'!H15) -> Mindbody higher | B15: =IF('Bedaya vs Mindbody'!A15="","",'Bedaya vs Mindbody'!A15) -> Boxing Gloves | C15: =IF('Bedaya vs Mindbody'!B15="","",'Bedaya vs Mindbody'!B15) -> 12 oz | D15: =IF('Bedaya vs Mindbody'!C15="","",'Bedaya vs Mindbody'!C15) -> Boxing Gloves | E15: =IF('Bedaya vs Mindbody'!D15="","",'Bedaya vs Mindbody'!D15) -> 12oz | F15: =IF('Bedaya vs Mindbody'!E15="","",'Bedaya vs Mindbody'!E15) -> 0 | G15: =IF('Bedaya vs Mindbody'!F15="","",'Bedaya vs Mindbody'!F15) -> 11 | H15: =IF('Bedaya vs Mindbody'!G15="","",'Bedaya vs Mindbody'!G15) -> -11 | I15: =IF('Bedaya vs Mindbody'!I15="","",'Bedaya vs Mindbody'!I15) -> Physical reduced by pairs transferred to Promenade on 19 Sep; Mindbody quantity not adjusted. Mindbody shows 11 vs 1 counted - recount / check for typo or unadjusted transfer
A16: =IF('Bedaya vs Mindbody'!H39="","",'Bedaya vs Mindbody'!H39) -> Mindbody higher | B16: =IF('Bedaya vs Mindbody'!A39="","",'Bedaya vs Mindbody'!A39) -> Kajukenbo Patch | C16: =IF('Bedaya vs Mindbody'!B39="","",'Bedaya vs Mindbody'!B39) -> (one line for both patches) | D16: =IF('Bedaya vs Mindbody'!C39="","",'Bedaya vs Mindbody'!C39) -> Kajukimbo Patch - Circle (Front) + Kajukimbo Patch - Shoulder | E16: =IF('Bedaya vs Mindbody'!D39="","",'Bedaya vs Mindbody'!D39) -> - + - | F16: =IF('Bedaya vs Mindbody'!E39="","",'Bedaya vs Mindbody'!E39) -> 51 | G16: =IF('Bedaya vs Mindbody'!F39="","",'Bedaya vs Mindbody'!F39) -> 62 | H16: =IF('Bedaya vs Mindbody'!G39="","",'Bedaya vs Mindbody'!G39) -> -11 | I16: =IF('Bedaya vs Mindbody'!I39="","",'Bedaya vs Mindbody'!I39) -> Circle 25 + Shoulder 26 compared with the single Mindbody line (Promenade patches excluded)
A17: =IF('Bedaya vs Mindbody'!H94="","",'Bedaya vs Mindbody'!H94) -> Mindbody higher | B17: =IF('Bedaya vs Mindbody'!A94="","",'Bedaya vs Mindbody'!A94) -> New Taekwondo | C17: =IF('Bedaya vs Mindbody'!B94="","",'Bedaya vs Mindbody'!B94) -> 150 | D17: =IF('Bedaya vs Mindbody'!C94="","",'Bedaya vs Mindbody'!C94) -> Taekwondo Uniform | E17: =IF('Bedaya vs Mindbody'!D94="","",'Bedaya vs Mindbody'!D94) -> 150cm | F17: =IF('Bedaya vs Mindbody'!E94="","",'Bedaya vs Mindbody'!E94) -> 3 | G17: =IF('Bedaya vs Mindbody'!F94="","",'Bedaya vs Mindbody'!F94) -> 5 | H17: =IF('Bedaya vs Mindbody'!G94="","",'Bedaya vs Mindbody'!G94) -> -2 | I17: =IF('Bedaya vs Mindbody'!I94="","",'Bedaya vs Mindbody'!I94)
A18: =IF('Bedaya vs Mindbody'!H99="","",'Bedaya vs Mindbody'!H99) -> Mindbody higher | B18: =IF('Bedaya vs Mindbody'!A99="","",'Bedaya vs Mindbody'!A99) -> Shin Guard | C18: =IF('Bedaya vs Mindbody'!B99="","",'Bedaya vs Mindbody'!B99) -> Extra Small | D18: =IF('Bedaya vs Mindbody'!C99="","",'Bedaya vs Mindbody'!C99) -> Shin Guard | E18: =IF('Bedaya vs Mindbody'!D99="","",'Bedaya vs Mindbody'!D99) -> XS | F18: =IF('Bedaya vs Mindbody'!E99="","",'Bedaya vs Mindbody'!E99) -> 0 | G18: =IF('Bedaya vs Mindbody'!F99="","",'Bedaya vs Mindbody'!F99) -> 2 | H18: =IF('Bedaya vs Mindbody'!G99="","",'Bedaya vs Mindbody'!G99) -> -2 | I18: =IF('Bedaya vs Mindbody'!I99="","",'Bedaya vs Mindbody'!I99) -> Physical reduced by pairs transferred to Promenade on 19 Sep; Mindbody quantity not adjusted.
A19: =IF('Bedaya vs Mindbody'!H100="","",'Bedaya vs Mindbody'!H100) -> Mindbody higher | B19: =IF('Bedaya vs Mindbody'!A100="","",'Bedaya vs Mindbody'!A100) -> Shin Guard | C19: =IF('Bedaya vs Mindbody'!B100="","",'Bedaya vs Mindbody'!B100) -> Small | D19: =IF('Bedaya vs Mindbody'!C100="","",'Bedaya vs Mindbody'!C100) -> Shin Guard | E19: =IF('Bedaya vs Mindbody'!D100="","",'Bedaya vs Mindbody'!D100) -> S | F19: =IF('Bedaya vs Mindbody'!E100="","",'Bedaya vs Mindbody'!E100) -> 0 | G19: =IF('Bedaya vs Mindbody'!F100="","",'Bedaya vs Mindbody'!F100) -> 1 | H19: =IF('Bedaya vs Mindbody'!G100="","",'Bedaya vs Mindbody'!G100) -> -1 | I19: =IF('Bedaya vs Mindbody'!I100="","",'Bedaya vs Mindbody'!I100) -> Physical reduced by pairs transferred to Promenade on 19 Sep; Mindbody quantity not adjusted.
A20: =IF('Bedaya vs Mindbody'!H101="","",'Bedaya vs Mindbody'!H101) -> Mindbody higher | B20: =IF('Bedaya vs Mindbody'!A101="","",'Bedaya vs Mindbody'!A101) -> Shin Guard | C20: =IF('Bedaya vs Mindbody'!B101="","",'Bedaya vs Mindbody'!B101) -> Medium | D20: =IF('Bedaya vs Mindbody'!C101="","",'Bedaya vs Mindbody'!C101) -> Shin Guard | E20: =IF('Bedaya vs Mindbody'!D101="","",'Bedaya vs Mindbody'!D101) -> M | F20: =IF('Bedaya vs Mindbody'!E101="","",'Bedaya vs Mindbody'!E101) -> -1 | G20: =IF('Bedaya vs Mindbody'!F101="","",'Bedaya vs Mindbody'!F101) -> 1 | H20: =IF('Bedaya vs Mindbody'!G101="","",'Bedaya vs Mindbody'!G101) -> -2 | I20: =IF('Bedaya vs Mindbody'!I101="","",'Bedaya vs Mindbody'!I101) -> Physical reduced by pairs transferred to Promenade on 19 Sep; Mindbody quantity not adjusted.
A21: =IF('Bedaya vs Mindbody'!H102="","",'Bedaya vs Mindbody'!H102) -> Mindbody higher | B21: =IF('Bedaya vs Mindbody'!A102="","",'Bedaya vs Mindbody'!A102) -> Shin Guard | C21: =IF('Bedaya vs Mindbody'!B102="","",'Bedaya vs Mindbody'!B102) -> Large | D21: =IF('Bedaya vs Mindbody'!C102="","",'Bedaya vs Mindbody'!C102) -> Shin Guard | E21: =IF('Bedaya vs Mindbody'!D102="","",'Bedaya vs Mindbody'!D102) -> L | F21: =IF('Bedaya vs Mindbody'!E102="","",'Bedaya vs Mindbody'!E102) -> 0 | G21: =IF('Bedaya vs Mindbody'!F102="","",'Bedaya vs Mindbody'!F102) -> 2 | H21: =IF('Bedaya vs Mindbody'!G102="","",'Bedaya vs Mindbody'!G102) -> -2 | I21: =IF('Bedaya vs Mindbody'!I102="","",'Bedaya vs Mindbody'!I102) -> Physical reduced by pairs transferred to Promenade on 19 Sep; Mindbody quantity not adjusted.
A22: =IF('Bedaya vs Mindbody'!H103="","",'Bedaya vs Mindbody'!H103) -> Mindbody higher | B22: =IF('Bedaya vs Mindbody'!A103="","",'Bedaya vs Mindbody'!A103) -> Shin Guard | C22: =IF('Bedaya vs Mindbody'!B103="","",'Bedaya vs Mindbody'!B103) -> Extra Large | D22: =IF('Bedaya vs Mindbody'!C103="","",'Bedaya vs Mindbody'!C103) -> Shin Guard | E22: =IF('Bedaya vs Mindbody'!D103="","",'Bedaya vs Mindbody'!D103) -> XL | F22: =IF('Bedaya vs Mindbody'!E103="","",'Bedaya vs Mindbody'!E103) -> -1 | G22: =IF('Bedaya vs Mindbody'!F103="","",'Bedaya vs Mindbody'!F103) -> 1 | H22: =IF('Bedaya vs Mindbody'!G103="","",'Bedaya vs Mindbody'!G103) -> -2 | I22: =IF('Bedaya vs Mindbody'!I103="","",'Bedaya vs Mindbody'!I103) -> Physical reduced by pairs transferred to Promenade on 19 Sep; Mindbody quantity not adjusted.
A23: =IF('Bedaya vs Mindbody'!H37="","",'Bedaya vs Mindbody'!H37) -> Not in Mindbody | B23: =IF('Bedaya vs Mindbody'!A37="","",'Bedaya vs Mindbody'!A37) -> Instructor Shirt | C23: =IF('Bedaya vs Mindbody'!B37="","",'Bedaya vs Mindbody'!B37) -> (no XL / L line) | D23: =IF('Bedaya vs Mindbody'!C37="","",'Bedaya vs Mindbody'!C37) -> Instructor T-shirt (Elite Logo) | E23: =IF('Bedaya vs Mindbody'!D37="","",'Bedaya vs Mindbody'!D37) -> XL | F23: =IF('Bedaya vs Mindbody'!E37="","",'Bedaya vs Mindbody'!E37) -> 3 | G23: =IF('Bedaya vs Mindbody'!F37="","",'Bedaya vs Mindbody'!F37) | H23: =IF('Bedaya vs Mindbody'!G37="","",'Bedaya vs Mindbody'!G37) | I23: =IF('Bedaya vs Mindbody'!I37="","",'Bedaya vs Mindbody'!I37) -> Mindbody only has Grey S and XXL (both 0)
A24: =IF('Bedaya vs Mindbody'!H38="","",'Bedaya vs Mindbody'!H38) -> Not in Mindbody | B24: =IF('Bedaya vs Mindbody'!A38="","",'Bedaya vs Mindbody'!A38) -> Instructor Shirt | C24: =IF('Bedaya vs Mindbody'!B38="","",'Bedaya vs Mindbody'!B38) -> (no XL / L line) | D24: =IF('Bedaya vs Mindbody'!C38="","",'Bedaya vs Mindbody'!C38) -> Instructor T-shirt (Elite Logo) | E24: =IF('Bedaya vs Mindbody'!D38="","",'Bedaya vs Mindbody'!D38) -> L | F24: =IF('Bedaya vs Mindbody'!E38="","",'Bedaya vs Mindbody'!E38) -> 1 | G24: =IF('Bedaya vs Mindbody'!F38="","",'Bedaya vs Mindbody'!F38) | H24: =IF('Bedaya vs Mindbody'!G38="","",'Bedaya vs Mindbody'!G38) | I24: =IF('Bedaya vs Mindbody'!I38="","",'Bedaya vs Mindbody'!I38) -> Mindbody only has Grey S and XXL (both 0)
A25: =IF('Bedaya vs Mindbody'!H49="","",'Bedaya vs Mindbody'!H49) -> Not in Mindbody | B25: =IF('Bedaya vs Mindbody'!A49="","",'Bedaya vs Mindbody'!A49) -> Kajukenbo Uniform w/ Patches | C25: =IF('Bedaya vs Mindbody'!B49="","",'Bedaya vs Mindbody'!B49) -> (no 190 line) | D25: =IF('Bedaya vs Mindbody'!C49="","",'Bedaya vs Mindbody'!C49) -> Kajukimbo Uniform | E25: =IF('Bedaya vs Mindbody'!D49="","",'Bedaya vs Mindbody'!D49) -> 190cm | F25: =IF('Bedaya vs Mindbody'!E49="","",'Bedaya vs Mindbody'!E49) -> 2 | G25: =IF('Bedaya vs Mindbody'!F49="","",'Bedaya vs Mindbody'!F49) | H25: =IF('Bedaya vs Mindbody'!G49="","",'Bedaya vs Mindbody'!G49) | I25: =IF('Bedaya vs Mindbody'!I49="","",'Bedaya vs Mindbody'!I49) -> Mindbody only has size 210 (0)
A26: =IF('Bedaya vs Mindbody'!H50="","",'Bedaya vs Mindbody'!H50) -> Not in Mindbody | B26: =IF('Bedaya vs Mindbody'!A50="","",'Bedaya vs Mindbody'!A50) -> Kajukenbo Uniform w/ Patches | C26: =IF('Bedaya vs Mindbody'!B50="","",'Bedaya vs Mindbody'!B50) -> (no 200 line) | D26: =IF('Bedaya vs Mindbody'!C50="","",'Bedaya vs Mindbody'!C50) -> Kajukimbo Uniform | E26: =IF('Bedaya vs Mindbody'!D50="","",'Bedaya vs Mindbody'!D50) -> 200cm | F26: =IF('Bedaya vs Mindbody'!E50="","",'Bedaya vs Mindbody'!E50) -> 2 | G26: =IF('Bedaya vs Mindbody'!F50="","",'Bedaya vs Mindbody'!F50) | H26: =IF('Bedaya vs Mindbody'!G50="","",'Bedaya vs Mindbody'!G50) | I26: =IF('Bedaya vs Mindbody'!I50="","",'Bedaya vs Mindbody'!I50) -> Mindbody only has size 210 (0)
A27: =IF('Bedaya vs Mindbody'!H69="","",'Bedaya vs Mindbody'!H69) -> Not in Mindbody | B27: =IF('Bedaya vs Mindbody'!A69="","",'Bedaya vs Mindbody'!A69) -> Mouth Guard | C27: =IF('Bedaya vs Mindbody'!B69="","",'Bedaya vs Mindbody'!B69) -> (no Junior line) | D27: =IF('Bedaya vs Mindbody'!C69="","",'Bedaya vs Mindbody'!C69) -> Mouth Guard | E27: =IF('Bedaya vs Mindbody'!D69="","",'Bedaya vs Mindbody'!D69) -> Junior | F27: =IF('Bedaya vs Mindbody'!E69="","",'Bedaya vs Mindbody'!E69) -> 12 | G27: =IF('Bedaya vs Mindbody'!F69="","",'Bedaya vs Mindbody'!F69) | H27: =IF('Bedaya vs Mindbody'!G69="","",'Bedaya vs Mindbody'!G69) | I27: =IF('Bedaya vs Mindbody'!I69="","",'Bedaya vs Mindbody'!I69) -> No Junior mouth guard in Mindbody
A28: =IF('Bedaya vs Mindbody'!H88="","",'Bedaya vs Mindbody'!H88) -> Not in Mindbody | B28: =IF('Bedaya vs Mindbody'!A88="","",'Bedaya vs Mindbody'!A88) -> New Karate | C28: =IF('Bedaya vs Mindbody'!B88="","",'Bedaya vs Mindbody'!B88) -> (no 190 line) | D28: =IF('Bedaya vs Mindbody'!C88="","",'Bedaya vs Mindbody'!C88) -> Karate Uniform | E28: =IF('Bedaya vs Mindbody'!D88="","",'Bedaya vs Mindbody'!D88) -> 190cm | F28: =IF('Bedaya vs Mindbody'!E88="","",'Bedaya vs Mindbody'!E88) -> 2 | G28: =IF('Bedaya vs Mindbody'!F88="","",'Bedaya vs Mindbody'!F88) | H28: =IF('Bedaya vs Mindbody'!G88="","",'Bedaya vs Mindbody'!G88) | I28: =IF('Bedaya vs Mindbody'!I88="","",'Bedaya vs Mindbody'!I88) -> No 190 size in Mindbody
A29: =IF('Bedaya vs Mindbody'!H105="","",'Bedaya vs Mindbody'!H105) -> Not in Mindbody | B29: =IF('Bedaya vs Mindbody'!A105="","",'Bedaya vs Mindbody'!A105) -> Supporter | C29: =IF('Bedaya vs Mindbody'!B105="","",'Bedaya vs Mindbody'!B105) -> (not in Mindbody) | D29: =IF('Bedaya vs Mindbody'!C105="","",'Bedaya vs Mindbody'!C105) -> Supporter | E29: =IF('Bedaya vs Mindbody'!D105="","",'Bedaya vs Mindbody'!D105) -> M | F29: =IF('Bedaya vs Mindbody'!E105="","",'Bedaya vs Mindbody'!E105) -> 7 | G29: =IF('Bedaya vs Mindbody'!F105="","",'Bedaya vs Mindbody'!F105) | H29: =IF('Bedaya vs Mindbody'!G105="","",'Bedaya vs Mindbody'!G105) | I29: =IF('Bedaya vs Mindbody'!I105="","",'Bedaya vs Mindbody'!I105) -> No supporter / groin guard product in Mindbody
A30: =IF('Bedaya vs Mindbody'!H106="","",'Bedaya vs Mindbody'!H106) -> Not in Mindbody | B30: =IF('Bedaya vs Mindbody'!A106="","",'Bedaya vs Mindbody'!A106) -> Supporter | C30: =IF('Bedaya vs Mindbody'!B106="","",'Bedaya vs Mindbody'!B106) -> (not in Mindbody) | D30: =IF('Bedaya vs Mindbody'!C106="","",'Bedaya vs Mindbody'!C106) -> Supporter | E30: =IF('Bedaya vs Mindbody'!D106="","",'Bedaya vs Mindbody'!D106) -> S | F30: =IF('Bedaya vs Mindbody'!E106="","",'Bedaya vs Mindbody'!E106) -> 9 | G30: =IF('Bedaya vs Mindbody'!F106="","",'Bedaya vs Mindbody'!F106) | H30: =IF('Bedaya vs Mindbody'!G106="","",'Bedaya vs Mindbody'!G106) | I30: =IF('Bedaya vs Mindbody'!I106="","",'Bedaya vs Mindbody'!I106) -> No supporter / groin guard product in Mindbody
A31: =IF('Bedaya vs Mindbody'!H109="","",'Bedaya vs Mindbody'!H109) -> Not in Mindbody | B31: =IF('Bedaya vs Mindbody'!A109="","",'Bedaya vs Mindbody'!A109) -> Systema Shirt | C31: =IF('Bedaya vs Mindbody'!B109="","",'Bedaya vs Mindbody'!B109) -> (no Grey M line) | D31: =IF('Bedaya vs Mindbody'!C109="","",'Bedaya vs Mindbody'!C109) -> Systema T-shirt (Gray) | E31: =IF('Bedaya vs Mindbody'!D109="","",'Bedaya vs Mindbody'!D109) -> M | F31: =IF('Bedaya vs Mindbody'!E109="","",'Bedaya vs Mindbody'!E109) -> 1 | G31: =IF('Bedaya vs Mindbody'!F109="","",'Bedaya vs Mindbody'!F109) | H31: =IF('Bedaya vs Mindbody'!G109="","",'Bedaya vs Mindbody'!G109) | I31: =IF('Bedaya vs Mindbody'!I109="","",'Bedaya vs Mindbody'!I109) -> Mindbody only has Grey XL and XXX Large
A32: =IF('Bedaya vs Mindbody'!H110="","",'Bedaya vs Mindbody'!H110) -> Not in Mindbody | B32: =IF('Bedaya vs Mindbody'!A110="","",'Bedaya vs Mindbody'!A110) -> Systema Shirt | C32: =IF('Bedaya vs Mindbody'!B110="","",'Bedaya vs Mindbody'!B110) -> (no Grey S line) | D32: =IF('Bedaya vs Mindbody'!C110="","",'Bedaya vs Mindbody'!C110) -> Systema T-shirt (Gray) | E32: =IF('Bedaya vs Mindbody'!D110="","",'Bedaya vs Mindbody'!D110) -> S | F32: =IF('Bedaya vs Mindbody'!E110="","",'Bedaya vs Mindbody'!E110) -> 1 | G32: =IF('Bedaya vs Mindbody'!F110="","",'Bedaya vs Mindbody'!F110) | H32: =IF('Bedaya vs Mindbody'!G110="","",'Bedaya vs Mindbody'!G110) | I32: =IF('Bedaya vs Mindbody'!I110="","",'Bedaya vs Mindbody'!I110) -> Mindbody only has Grey XL and XXX Large
A33: =IF('Bedaya vs Mindbody'!H115="","",'Bedaya vs Mindbody'!H115) -> Not in Mindbody | B33: =IF('Bedaya vs Mindbody'!A115="","",'Bedaya vs Mindbody'!A115) -> (no Mindbody product) | C33: =IF('Bedaya vs Mindbody'!B115="","",'Bedaya vs Mindbody'!B115) -> Karate Uniform - 120cm | D33: =IF('Bedaya vs Mindbody'!C115="","",'Bedaya vs Mindbody'!C115) -> Karate Uniform (No Logo) | E33: =IF('Bedaya vs Mindbody'!D115="","",'Bedaya vs Mindbody'!D115) -> 120cm | F33: =IF('Bedaya vs Mindbody'!E115="","",'Bedaya vs Mindbody'!E115) -> 48 | G33: =IF('Bedaya vs Mindbody'!F115="","",'Bedaya vs Mindbody'!F115) | H33: =IF('Bedaya vs Mindbody'!G115="","",'Bedaya vs Mindbody'!G115) | I33: =IF('Bedaya vs Mindbody'!I115="","",'Bedaya vs Mindbody'!I115) -> Old / no-logo / no-program stock - not listed in Mindbody
A34: =IF('Bedaya vs Mindbody'!H116="","",'Bedaya vs Mindbody'!H116) -> Not in Mindbody | B34: =IF('Bedaya vs Mindbody'!A116="","",'Bedaya vs Mindbody'!A116) -> (no Mindbody product) | C34: =IF('Bedaya vs Mindbody'!B116="","",'Bedaya vs Mindbody'!B116) -> Karate Uniform - 110cm | D34: =IF('Bedaya vs Mindbody'!C116="","",'Bedaya vs Mindbody'!C116) -> Karate Uniform (No Logo) | E34: =IF('Bedaya vs Mindbody'!D116="","",'Bedaya vs Mindbody'!D116) -> 110cm | F34: =IF('Bedaya vs Mindbody'!E116="","",'Bedaya vs Mindbody'!E116) -> 95 | G34: =IF('Bedaya vs Mindbody'!F116="","",'Bedaya vs Mindbody'!F116) | H34: =IF('Bedaya vs Mindbody'!G116="","",'Bedaya vs Mindbody'!G116) | I34: =IF('Bedaya vs Mindbody'!I116="","",'Bedaya vs Mindbody'!I116) -> Old / no-logo / no-program stock - not listed in Mindbody
A35: =IF('Bedaya vs Mindbody'!H117="","",'Bedaya vs Mindbody'!H117) -> Not in Mindbody | B35: =IF('Bedaya vs Mindbody'!A117="","",'Bedaya vs Mindbody'!A117) -> (no Mindbody product) | C35: =IF('Bedaya vs Mindbody'!B117="","",'Bedaya vs Mindbody'!B117) -> Karate Uniform - 100cm | D35: =IF('Bedaya vs Mindbody'!C117="","",'Bedaya vs Mindbody'!C117) -> Karate Uniform (No Logo) | E35: =IF('Bedaya vs Mindbody'!D117="","",'Bedaya vs Mindbody'!D117) -> 100cm | F35: =IF('Bedaya vs Mindbody'!E117="","",'Bedaya vs Mindbody'!E117) -> 40 | G35: =IF('Bedaya vs Mindbody'!F117="","",'Bedaya vs Mindbody'!F117) | H35: =IF('Bedaya vs Mindbody'!G117="","",'Bedaya vs Mindbody'!G117) | I35: =IF('Bedaya vs Mindbody'!I117="","",'Bedaya vs Mindbody'!I117) -> Old / no-logo / no-program stock - not listed in Mindbody
A36: =IF('Bedaya vs Mindbody'!H118="","",'Bedaya vs Mindbody'!H118) -> Not in Mindbody | B36: =IF('Bedaya vs Mindbody'!A118="","",'Bedaya vs Mindbody'!A118) -> (no Mindbody product) | C36: =IF('Bedaya vs Mindbody'!B118="","",'Bedaya vs Mindbody'!B118) -> Taekwondo Uniform - 110cm | D36: =IF('Bedaya vs Mindbody'!C118="","",'Bedaya vs Mindbody'!C118) -> Taekwondo Uniform (Old) | E36: =IF('Bedaya vs Mindbody'!D118="","",'Bedaya vs Mindbody'!D118) -> 110cm | F36: =IF('Bedaya vs Mindbody'!E118="","",'Bedaya vs Mindbody'!E118) -> 10 | G36: =IF('Bedaya vs Mindbody'!F118="","",'Bedaya vs Mindbody'!F118) | H36: =IF('Bedaya vs Mindbody'!G118="","",'Bedaya vs Mindbody'!G118) | I36: =IF('Bedaya vs Mindbody'!I118="","",'Bedaya vs Mindbody'!I118) -> Old / no-logo / no-program stock - not listed in Mindbody
A37: =IF('Bedaya vs Mindbody'!H119="","",'Bedaya vs Mindbody'!H119) -> Not in Mindbody | B37: =IF('Bedaya vs Mindbody'!A119="","",'Bedaya vs Mindbody'!A119) -> (no Mindbody product) | C37: =IF('Bedaya vs Mindbody'!B119="","",'Bedaya vs Mindbody'!B119) -> Taekwondo Uniform - 100cm | D37: =IF('Bedaya vs Mindbody'!C119="","",'Bedaya vs Mindbody'!C119) -> Taekwondo Uniform (Old) | E37: =IF('Bedaya vs Mindbody'!D119="","",'Bedaya vs Mindbody'!D119) -> 100cm | F37: =IF('Bedaya vs Mindbody'!E119="","",'Bedaya vs Mindbody'!E119) -> 13 | G37: =IF('Bedaya vs Mindbody'!F119="","",'Bedaya vs Mindbody'!F119) | H37: =IF('Bedaya vs Mindbody'!G119="","",'Bedaya vs Mindbody'!G119) | I37: =IF('Bedaya vs Mindbody'!I119="","",'Bedaya vs Mindbody'!I119) -> Old / no-logo / no-program stock - not listed in Mindbody
A38: =IF('Bedaya vs Mindbody'!H120="","",'Bedaya vs Mindbody'!H120) -> Not in Mindbody | B38: =IF('Bedaya vs Mindbody'!A120="","",'Bedaya vs Mindbody'!A120) -> (no Mindbody product) | C38: =IF('Bedaya vs Mindbody'!B120="","",'Bedaya vs Mindbody'!B120) -> Taekwondo Uniform - 130cm (upper only) | D38: =IF('Bedaya vs Mindbody'!C120="","",'Bedaya vs Mindbody'!C120) -> Taekwondo Uniform (Old) | E38: =IF('Bedaya vs Mindbody'!D120="","",'Bedaya vs Mindbody'!D120) -> 130cm (upper only) | F38: =IF('Bedaya vs Mindbody'!E120="","",'Bedaya vs Mindbody'!E120) -> 1 | G38: =IF('Bedaya vs Mindbody'!F120="","",'Bedaya vs Mindbody'!F120) | H38: =IF('Bedaya vs Mindbody'!G120="","",'Bedaya vs Mindbody'!G120) | I38: =IF('Bedaya vs Mindbody'!I120="","",'Bedaya vs Mindbody'!I120) -> Old / no-logo / no-program stock - not listed in Mindbody
A39: =IF('Bedaya vs Mindbody'!H121="","",'Bedaya vs Mindbody'!H121) -> Not in Mindbody | B39: =IF('Bedaya vs Mindbody'!A121="","",'Bedaya vs Mindbody'!A121) -> (no Mindbody product) | C39: =IF('Bedaya vs Mindbody'!B121="","",'Bedaya vs Mindbody'!B121) -> Judo Uniform - 140cm | D39: =IF('Bedaya vs Mindbody'!C121="","",'Bedaya vs Mindbody'!C121) -> Judo Uniform (With Logo) | E39: =IF('Bedaya vs Mindbody'!D121="","",'Bedaya vs Mindbody'!D121) -> 140cm | F39: =IF('Bedaya vs Mindbody'!E121="","",'Bedaya vs Mindbody'!E121) -> 12 | G39: =IF('Bedaya vs Mindbody'!F121="","",'Bedaya vs Mindbody'!F121) | H39: =IF('Bedaya vs Mindbody'!G121="","",'Bedaya vs Mindbody'!G121) | I39: =IF('Bedaya vs Mindbody'!I121="","",'Bedaya vs Mindbody'!I121) -> Old / no-logo / no-program stock - not listed in Mindbody
A40: =IF('Bedaya vs Mindbody'!H122="","",'Bedaya vs Mindbody'!H122) -> Not in Mindbody | B40: =IF('Bedaya vs Mindbody'!A122="","",'Bedaya vs Mindbody'!A122) -> (no Mindbody product) | C40: =IF('Bedaya vs Mindbody'!B122="","",'Bedaya vs Mindbody'!B122) -> Judo Uniform - 130cm | D40: =IF('Bedaya vs Mindbody'!C122="","",'Bedaya vs Mindbody'!C122) -> Judo Uniform (With Logo) | E40: =IF('Bedaya vs Mindbody'!D122="","",'Bedaya vs Mindbody'!D122) -> 130cm | F40: =IF('Bedaya vs Mindbody'!E122="","",'Bedaya vs Mindbody'!E122) -> 9 | G40: =IF('Bedaya vs Mindbody'!F122="","",'Bedaya vs Mindbody'!F122) | H40: =IF('Bedaya vs Mindbody'!G122="","",'Bedaya vs Mindbody'!G122) | I40: =IF('Bedaya vs Mindbody'!I122="","",'Bedaya vs Mindbody'!I122) -> Old / no-logo / no-program stock - not listed in Mindbody
A41: =IF('Bedaya vs Mindbody'!H123="","",'Bedaya vs Mindbody'!H123) -> Not in Mindbody | B41: =IF('Bedaya vs Mindbody'!A123="","",'Bedaya vs Mindbody'!A123) -> (no Mindbody product) | C41: =IF('Bedaya vs Mindbody'!B123="","",'Bedaya vs Mindbody'!B123) -> Judo Uniform - 110cm (upper only) | D41: =IF('Bedaya vs Mindbody'!C123="","",'Bedaya vs Mindbody'!C123) -> Judo Uniform (With Logo) | E41: =IF('Bedaya vs Mindbody'!D123="","",'Bedaya vs Mindbody'!D123) -> 110cm (upper only) | F41: =IF('Bedaya vs Mindbody'!E123="","",'Bedaya vs Mindbody'!E123) -> 1 | G41: =IF('Bedaya vs Mindbody'!F123="","",'Bedaya vs Mindbody'!F123) | H41: =IF('Bedaya vs Mindbody'!G123="","",'Bedaya vs Mindbody'!G123) | I41: =IF('Bedaya vs Mindbody'!I123="","",'Bedaya vs Mindbody'!I123) -> Old / no-logo / no-program stock - not listed in Mindbody
